<?xml version="1.0"?>

<robot xmlns:xacro="http://www.ros.org/wiki/xacro">

    <xacro:property name="castor_radius" value="0.02"/>
    <xacro:property name="castor_mass" value="0.06"/>
    <xacro:macro name="inching_unit" params="name">
        <link name="${name}">
            <visual>
                <geometry>
                    <box size="${chassis_width} ${chassis_width} ${chassis_depth}"/>
                </geometry>
                <material name="white">
                    <color rgba="1 1 1 1"/>
                </material>
            </visual> 
            <collision>
                <geometry>
                    <box size="${chassis_width} ${chassis_width} ${chassis_depth}"/>
                </geometry>
            </collision>
            <xacro:box_inertia m="0.5" w="${chassis_width}" h="${chassis_width}" d="${chassis_depth}"/>
        </link>
  </xacro:macro>
    <!--Actuator Macro-->
  <xacro:macro name="acc_cylinder" params="name">
        <link name="${name}">
            <visual>
                <geometry>
                    <cylinder radius="${incher_width_i}" length="${incher_length_i}"/>
                </geometry>
                <material name="white">
                    <color rgba="1 1 1 1"/>
                </material>
            </visual>
            <collision>
                <geometry>
                    <cylinder radius="${incher_width_i}" length="${incher_length_i}"/>
                </geometry>
            </collision>
            <xacro:cylinder_inertia m="0.03" r="${incher_width_i}" l="${incher_length_i}"/>
        </link>
    </xacro:macro>

  <xacro:macro name="acc_box" params="name">
        <link name="${name}">
            <visual>
                <geometry>
                    <box size="${incher_radius_o} ${incher_radius_o} ${incher_length_o}"/>
                </geometry>
                <material name="white">
                    <color rgba="1 1 1 1"/>
                </material>
            </visual>
            <collision>
                <geometry>
                    <box size="${incher_radius_o} ${incher_radius_o} ${incher_length_o}"/>
                </geometry>
            </collision>
            <xacro:box_inertia m="0.05" w="${incher_radius_o}" h="${incher_radius_o}" d="${incher_length_o}"/>
        </link>
  </xacro:macro>
  
  <!-- Gripper End Effector Macro -->
  <xacro:macro name="gripper" params="name">
        <link name="${name}">
            <visual>
                <geometry>
                  <!--Gripper Model-->
                  <sphere radius="${castor_radius}"/>
                </geometry>
                <material name="blue">
                    <color rgba="0 0 1 1"/>
                </material>
            </visual>
            <collision>
                <geometry>
                    <!--Gripper Model-->
                    <sphere radius="${castor_radius}"/>
                </geometry>
            </collision>
            <xacro:sphere_inertia m="${castor_mass}" r="${castor_radius}"/>
        </link>
    </xacro:macro>

<xacro:macro name="full_inching_unit" params="number base">
        <!-- LINKS -->

        <!-- Inching Links -->
        <xacro:inching_unit name="inching_unit_bottom_${number}"/>

        <xacro:acc_cylinder name="incher_top1_${number}"/>

        <xacro:acc_cylinder name="incher_bottom1_${number}"/>

        <xacro:acc_cylinder name="incher_top2_${number}"/>

        <xacro:acc_cylinder name="incher_bottom2_${number}"/>

        <xacro:acc_cylinder name="incher_top3_${number}"/>

        <xacro:acc_cylinder name="incher_bottom3_${number}"/>

        <xacro:acc_cylinder name="incher_top4_${number}"/>

        <xacro:acc_cylinder name="incher_bottom4_${number}"/>

        <xacro:inching_unit name="inching_unit_top_${number}"/>

        <!-- Gripper Top Links Outside-->
        <xacro:acc_box name="gripper_top_left_outside_i_${number}"/>

        <xacro:acc_cylinder name="gripper_top_left_outside_o_${number}"/>

        <xacro:acc_box name="gripper_top_right_outside_i_${number}"/>

        <xacro:acc_cylinder name="gripper_top_right_outside_o_${number}"/>

        <!-- Gripper Top Links Inside-->
        <xacro:acc_box name="gripper_top_left_inside_i_${number}"/>

        <xacro:acc_cylinder name="gripper_top_left_inside_o_${number}"/>

        <xacro:acc_box name="gripper_top_right_inside_i_${number}"/>

        <xacro:acc_cylinder name="gripper_top_right_inside_o_${number}"/>


        <!-- Gripper Bottom Links Outside -->
        <xacro:acc_box name="gripper_bottom_left_outside_i_${number}"/>

        <xacro:acc_cylinder name="gripper_bottom_left_outside_o_${number}"/>

        <xacro:acc_box name="gripper_bottom_right_outside_i_${number}"/>

        <xacro:acc_cylinder name="gripper_bottom_right_outside_o_${number}"/>

        <!-- Gripper Bottom Links Inside -->
        <xacro:acc_box name="gripper_bottom_left_inside_i_${number}"/>

        <xacro:acc_cylinder name="gripper_bottom_left_inside_o_${number}"/>

        <xacro:acc_box name="gripper_bottom_right_inside_i_${number}"/>

        <xacro:acc_cylinder name="gripper_bottom_right_inside_o_${number}"/>

        <!-- Gripper End Effectors Outside -->
        <xacro:gripper name="gripper_bottom_left_${number}"/>

        <xacro:gripper name="gripper_bottom_right_${number}"/>

        <xacro:gripper name="gripper_top_left_${number}"/>

        <xacro:gripper name="gripper_top_right_${number}"/>
        <!-- Gripper End Effectors Inside -->
        <xacro:gripper name="gripper_bottom_left2_${number}"/>

        <xacro:gripper name="gripper_bottom_right2_${number}"/>

        <xacro:gripper name="gripper_top_left2_${number}"/>

        <xacro:gripper name="gripper_top_right2_${number}"/>
        <!-- BASE JOINTS -->

        <joint name="base_joint_${number}" type="fixed">
            <parent link="${base}"/>
            <child link="inching_unit_bottom_${number}"/>
            <origin xyz="0 0 0" rpy="0 0 0"/>
        </joint>

        <!--Inching joints-->
        <joint name="inching_incher_bottom1_joint_${number}" type="fixed">
            <parent link="inching_unit_bottom_${number}"/>
            <child link="incher_bottom1_${number}"/>
            <origin xyz="0.125 0.125 0.075" rpy="0 0 0"/>
        </joint>
        <joint name="inching_incher_bottom2_joint_${number}" type="fixed">
            <parent link="inching_unit_bottom_${number}"/>
            <child link="incher_bottom2_${number}"/>
            <origin xyz="-0.125 0.125 0.075" rpy="0 0 0"/>
        </joint>
        <joint name="inching_incher_bottom3_joint_${number}" type="fixed">
            <parent link="inching_unit_bottom_${number}"/>
            <child link="incher_bottom3_${number}"/>
            <origin xyz="0.125 -0.125 0.075" rpy="0 0 0"/>
        </joint>
        <joint name="inching_incher_bottom4_joint_${number}" type="fixed">
            <parent link="inching_unit_bottom_${number}"/>
            <child link="incher_bottom4_${number}"/>
            <origin xyz="-0.125 -0.125 0.075" rpy="0 0 0"/>
        </joint>
        <joint name="incher1_joint_${number}" type="prismatic">
            <parent link="incher_bottom1_${number}"/>
            <child link="incher_top1_${number}"/>
            <origin xyz="0 0 0.0" rpy="0 0 0"/>
            <axis xyz="0 0 1"/>
            <limit lower="0" upper="0.150" effort="1000" velocity="0.2"/>
        </joint>

        <joint name="incher2_joint_${number}" type="prismatic">
            <parent link="incher_bottom2_${number}"/>
            <child link="incher_top2_${number}"/>
            <origin xyz="0 0 0.0" rpy="0 0 0"/>
            <axis xyz="0 0 1"/>
            <limit lower="0" upper="0.150" effort="1000" velocity="0.2"/>
        </joint>
        <joint name="incher3_joint_${number}" type="prismatic">
            <parent link="incher_bottom3_${number}"/>
            <child link="incher_top3_${number}"/>
            <origin xyz="0 0 0.0" rpy="0 0 0"/>
            <axis xyz="0 0 1"/>
            <limit lower="0" upper="0.150" effort="1000" velocity="0.2"/>
        </joint>
        <joint name="incher4_joint_${number}" type="prismatic">
            <parent link="incher_bottom4_${number}"/>
            <child link="incher_top4_${number}"/>
            <origin xyz="0 0 0.0" rpy="0 0 0"/>
            <axis xyz="0 0 1"/>
            <limit lower="0" upper="0.150" effort="1000" velocity="0.2"/>
        </joint>

        <joint name="inching_incher_top1_joint_${number}" type="fixed">
            <parent link="incher_top1_${number}"/>
            <child link="inching_unit_top_${number}"/>
            <origin xyz="-0.125 -0.125 0.075" rpy="0 0 0"/> 
        </joint>

        <!--Gripper Joints Top Outside-->

        <joint name="inching_gripper_topL_outside_joint_${number}" type="fixed">
            <parent link="inching_unit_top_${number}"/>
            <child link="gripper_top_left_outside_i_${number}"/>
            <origin xyz="-0.1 0.025 0" rpy="-1.57 0 0"/> 
        </joint>

        <joint name="inching_gripper_topR_outide_joint_${number}" type="fixed">
            <parent link="inching_unit_top_${number}"/>
            <child link="gripper_top_right_outside_i_${number}"/>
            <origin xyz="0.1 -0.025 0" rpy="1.57 0 0"/> 
        </joint>

        <joint name="gripper_topL_outside_joint_${number}" type="prismatic"> 
            <parent link="gripper_top_left_outside_i_${number}"/>
            <child link="gripper_top_left_outside_o_${number}"/>  
            <origin xyz="0 0 0" rpy="0 0 0"/>
            <axis xyz="0 0 1"/>
            <limit lower="0" upper="0.150" effort="1000" velocity="0.2"/>
        </joint>

        <joint name="gripper_topR_outside_joint_${number}" type="prismatic">  
            <parent link="gripper_top_right_outside_i_${number}"/>
            <child link="gripper_top_right_outside_o_${number}"/> 
            <origin xyz="0 0 0" rpy="0 0 0"/>
            <axis xyz="0 0 1"/>
            <limit lower="0" upper="0.150" effort="1000" velocity="0.2"/>
        </joint>
        <!--Gripper Joints Top Inside-->

        <joint name="inching_gripper_topL_inside_joint_${number}" type="fixed">
            <parent link="inching_unit_top_${number}"/>
            <child link="gripper_top_left_inside_i_${number}"/>
            <origin xyz="0.06 0.025 0" rpy="-1.57 0 0"/> 
        </joint>

        <joint name="inching_gripper_topR_inside_joint_${number}" type="fixed">
            <parent link="inching_unit_top_${number}"/>
            <child link="gripper_top_right_inside_i_${number}"/>
            <origin xyz="-0.06 -0.025 0" rpy="1.57 0 0"/> 
        </joint>

        <joint name="gripper_topL_inside_joint_${number}" type="prismatic"> 
            <parent link="gripper_top_left_inside_i_${number}"/>
            <child link="gripper_top_left_inside_o_${number}"/>  
            <origin xyz="0 0 0" rpy="0 0 0"/>
            <axis xyz="0 0 1"/>
            <limit lower="0" upper="0.150" effort="1000" velocity="0.2"/>
        </joint>

        <joint name="gripper_topR_inside_joint_${number}" type="prismatic">  
            <parent link="gripper_top_right_inside_i_${number}"/>
            <child link="gripper_top_right_inside_o_${number}"/> 
            <origin xyz="0 0 0" rpy="0 0 0"/>
            <axis xyz="0 0 1"/>
            <limit lower="0" upper="0.150" effort="1000" velocity="0.2"/>
        </joint>
        <!--Gripper Joints Bottom Outside-->

        <joint name="inching_gripper_bottomL_outside_joint_${number}" type="fixed">
            <parent link="inching_unit_bottom_${number}"/>
            <child link="gripper_bottom_left_outside_i_${number}"/>
            <origin xyz="-0.1 -0.0250 0" rpy="1.57 0 0"/> 
        </joint>

        <joint name="inching_gripper_bottomR_outside_joint_${number}" type="fixed">
            <parent link="inching_unit_bottom_${number}"/>
            <child link="gripper_bottom_right_outside_i_${number}"/>
            <origin xyz="0.1 0.025 0" rpy="-1.57 0 0"/> 
        </joint>

        <joint name="gripper_bottomL_outside_joint_${number}" type="prismatic"> 
            <parent link="gripper_bottom_left_outside_i_${number}"/>
            <child link="gripper_bottom_left_outside_o_${number}"/>  
            <origin xyz="0 0 0" rpy="0 0 0"/>
            <axis xyz="0 0 1"/>
            <limit lower="0" upper="0.150" effort="1000" velocity="0.2"/>
        </joint>

        <joint name="gripper_bottomR_outside_joint_${number}" type="prismatic">  
            <parent link="gripper_bottom_right_outside_i_${number}"/>
            <child link="gripper_bottom_right_outside_o_${number}"/> 
            <origin xyz="0 0 0" rpy="0 0 0"/>
            <axis xyz="0 0 1"/>
            <limit lower="0" upper="0.150" effort="1000" velocity="0.2"/>
        </joint>
        <!--Gripper Joints Bottom inside-->

        <joint name="inching_gripper_bottomL_inside_joint_${number}" type="fixed">
            <parent link="inching_unit_bottom_${number}"/>
            <child link="gripper_bottom_left_inside_i_${number}"/>
            <origin xyz="0.06 -0.0250 0" rpy="1.57 0 0"/> 
        </joint>

        <joint name="inching_gripper_bottomR_inside_joint_${number}" type="fixed">
            <parent link="inching_unit_bottom_${number}"/>
            <child link="gripper_bottom_right_inside_i_${number}"/>
            <origin xyz="-0.06 0.025 0" rpy="-1.57 0 0"/> 
        </joint>

        <joint name="gripper_bottomL_inside_joint_${number}" type="prismatic"> 
            <parent link="gripper_bottom_left_inside_i_${number}"/>
            <child link="gripper_bottom_left_inside_o_${number}"/>  
            <origin xyz="0 0 0" rpy="0 0 0"/>
            <axis xyz="0 0 1"/>
            <limit lower="0" upper="0.150" effort="1000" velocity="0.2"/>
        </joint>

        <joint name="gripper_bottomR_inside_joint_${number}" type="prismatic">  
            <parent link="gripper_bottom_right_inside_i_${number}"/>
            <child link="gripper_bottom_right_inside_o_${number}"/> 
            <origin xyz="0 0 0" rpy="0 0 0"/>
            <axis xyz="0 0 1"/>
            <limit lower="0" upper="0.150" effort="1000" velocity="0.2"/>
        </joint>


        <!--Gripper End Effectors Outside-->

        <joint name="gripper_end_bottomL_outside_joint_${number}" type="fixed">
            <parent link="gripper_bottom_left_outside_o_${number}"/>
            <child link="gripper_bottom_left_${number}"/>
            <origin xyz="0 0 0.075" rpy="0 0 0"/> 
        </joint>

        <joint name="gripper_end_bottomR_outside_joint_${number}" type="fixed">
            <parent link="gripper_bottom_right_outside_o_${number}"/>
            <child link="gripper_bottom_right_${number}"/>
            <origin xyz="0 0 0.075" rpy="0 0 0"/> 
        </joint>

        <joint name="gripper_end_topL_outside_joint_${number}" type="fixed">
            <parent link="gripper_top_left_outside_o_${number}"/>
            <child link="gripper_top_left_${number}"/>
            <origin xyz="0 0 0.075" rpy="0 0 0"/> 
        </joint>

        <joint name="gripper_end_topR_outside_joint_${number}" type="fixed">
            <parent link="gripper_top_right_outside_o_${number}"/>
            <child link="gripper_top_right_${number}"/>
            <origin xyz="0 0 0.075" rpy="0 0 0"/> 
        </joint>


        <!--Gripper End Effectors inside-->

        <joint name="gripper_end_bottomL_inside_joint_${number}" type="fixed">
            <parent link="gripper_bottom_left_inside_o_${number}"/>
            <child link="gripper_bottom_left2_${number}"/>
            <origin xyz="0 0 0.075" rpy="0 0 0"/> 
        </joint>

        <joint name="gripper_end_bottomR_inside_joint_${number}" type="fixed">
            <parent link="gripper_bottom_right_inside_o_${number}"/>
            <child link="gripper_bottom_right2_${number}"/>
            <origin xyz="0 0 0.075" rpy="0 0 0"/> 
        </joint>

        <joint name="gripper_end_topL_inside_joint_${number}" type="fixed">
            <parent link="gripper_top_left_inside_o_${number}"/>
            <child link="gripper_top_left2_${number}"/>
            <origin xyz="0 0 0.075" rpy="0 0 0"/> 
        </joint>

        <joint name="gripper_end_topR_inside_joint_${number}" type="fixed">
            <parent link="gripper_top_right_inside_o_${number}"/>
            <child link="gripper_top_right2_${number}"/>
            <origin xyz="0 0 0.075" rpy="0 0 0"/> 
        </joint>
    </xacro:macro>
</robot>
